Workbook

Sheet Скорость работы команды
B1: Скорость работы команды
C2: ВНЕСИТЕ СВОИ ДАННЫЕ В ЯЧЕЙКИ C4:J9
B3: № спринт | C3: 1 | D3: 2 | E3: 3 | F3: 4 | G3: 5 | H3: 6 | I3: 7 | J3: 8 | K3: Итого
A4: Задачи | B4: Взято задач на спринт | C4: 12 | D4: 12 | E4: 6 | K4: =SUM(C4:J4)
B5: Выполнено задач | C5: 10 | D5: 7 | E5: 2 | K5: =SUM(C5:J5)
A6: Story points | B6: Взято SP на спринт | C6: 42 | D6: 55 | E6: 28 | K6: =SUM(C6:J6)
B7: Выполнено SP | C7: 34 | D7: 29 | E7: 5 | K7: =SUM(C7:J7)
A8: Время | B8: Планируемое время выполенения задач на спринт | C8: 40 | D8: 110 | E8: 31 | K8: =SUM(C8:J8)
A9: (часов) | B9: Затраченнон время на спринт | C9: 34.5 | D9: 69.5 | E9: 13.75 | K9: =SUM(C9:J9)

Sheet Время работы команды
A1: Время работы команды в рамках спринтов | P1: Категории задач
A2: Выделяйте 2 разными цветами задачи четных и нечетных спринтов | P2: doc- задача по разработке документации,
F3: Время | J3: Исполнитель | K3: Константин | L3: Евгений | M3: Тамара | N3: Антон | P3: study- задача по изучению материала, чтобы в дальнейшем применить при разработке проекта,
A4: № спринта | B4: №задачи | C4: Название задачи | D4: Категория задачи | E4: Исполнитель | F4: Планируемое | G4: Реальное | J4: Sprint 1 | K4: =SUMIFS($G$5:$G$200,$E$5:$E$200,K$3,$A$5:$A$200,VALUE(RIGHT($J4,1))) | L4: =SUMIFS($G$5:$G$200,$E$5:$E$200,L$3,$A$5:$A$200,VALUE(RIGHT($J4,1))) | M4: =SUMIFS($G$5:$G$200,$E$5:$E$200,M$3,$A$5:$A$200,VALUE(RIGHT($J4,1))) | N4: =SUMIFS($G$5:$G$200,$E$5:$E$200,N$3,$A$5:$A$200,VALUE(RIGHT($J4,1))) | O4: =SUM(K4:N4) | P4: BE - задача связанная с back end, сюда же входят и задачи по проектирования БД,
A5: 1 | B5: 1 | C5: SCRUM-1: Обсуждение примерного дизайна | D5: org | E5: Константин | F5: 1 | G5: 1 | H5: =SUM(G5:G34) | J5: Sprint 2 | K5: =SUMIFS($G$5:$G$200,$E$5:$E$200,K$3,$A$5:$A$200,VALUE(RIGHT($J5,1))) | L5: =SUMIFS($G$5:$G$200,$E$5:$E$200,L$3,$A$5:$A$200,VALUE(RIGHT($J5,1))) | M5: =SUMIFS($G$5:$G$200,$E$5:$E$200,M$3,$A$5:$A$200,VALUE(RIGHT($J5,1))) | N5: =SUMIFS($G$5:$G$200,$E$5:$E$200,N$3,$A$5:$A$200,VALUE(RIGHT($J5,1))) | O5: =SUM(K5:N5) | P5: UI - задача по разработке user interface, например создание динамического прототипа в Figma,
A6: 1 | B6: 2 | C6: SCRUM-2: Обговор деталей и предполагаемой работы | D6: org | E6: Константин | F6: 2 | G6: 2 | J6: Sprint 3 | K6: =SUMIFS($G$5:$G$200,$E$5:$E$200,K$3,$A$5:$A$200,VALUE(RIGHT($J6,1))) | L6: =SUMIFS($G$5:$G$200,$E$5:$E$200,L$3,$A$5:$A$200,VALUE(RIGHT($J6,1))) | M6: =SUMIFS($G$5:$G$200,$E$5:$E$200,M$3,$A$5:$A$200,VALUE(RIGHT($J6,1))) | N6: =SUMIFS($G$5:$G$200,$E$5:$E$200,N$3,$A$5:$A$200,VALUE(RIGHT($J6,1))) | O6: =SUM(K6:N6) | P6: FE - front end задача,
A7: 1 | B7: 3 | C7: Создание Jira-доски, репозитория GitHub, Gitflow | D7: env | E7: Константин | F7: 3 | G7: 3 | J7: Sprint 4 | K7: =SUMIFS($G$5:$G$200,$E$5:$E$200,K$3,$A$5:$A$200,VALUE(RIGHT($J7,1))) | L7: =SUMIFS($G$5:$G$200,$E$5:$E$200,L$3,$A$5:$A$200,VALUE(RIGHT($J7,1))) | M7: =SUMIFS($G$5:$G$200,$E$5:$E$200,M$3,$A$5:$A$200,VALUE(RIGHT($J7,1))) | N7: =SUMIFS($G$5:$G$200,$E$5:$E$200,N$3,$A$5:$A$200,VALUE(RIGHT($J7,1))) | O7: =SUM(K7:N7) | P7: tests- задача по тестированию (разработка модульных тестов, тестирование функциональности проекта),
A8: 1 | B8: 4 | C8: Docker Compose и CI (Ruff + Pytest) | D8: env | E8: Константин | F8: 5 | G8: 5 | J8: Sprint 5 | K8: =SUMIFS($G$5:$G$200,$E$5:$E$200,K$3,$A$5:$A$200,VALUE(RIGHT($J8,1))) | L8: =SUMIFS($G$5:$G$200,$E$5:$E$200,L$3,$A$5:$A$200,VALUE(RIGHT($J8,1))) | M8: =SUMIFS($G$5:$G$200,$E$5:$E$200,M$3,$A$5:$A$200,VALUE(RIGHT($J8,1))) | N8: =SUMIFS($G$5:$G$200,$E$5:$E$200,N$3,$A$5:$A$200,VALUE(RIGHT($J8,1))) | O8: =SUM(K8:N8) | P8: env - задача по подготовке окружения (environment), создание доски, репозитория, установка ПО, а также DevOps задачи по обеспечению эффективной и безопасной работы систем, автоматизация процессов развертывания инфраструктуры, приложений и резервное копирование и т.д.,
A9: 1 | B9: 5 | C9: SCRUM-9: Устав проекта | D9: doc | E9: Антон | F9: 3 | G9: 3 | J9: Sprint 6 | K9: =SUMIFS($G$5:$G$200,$E$5:$E$200,K$3,$A$5:$A$200,VALUE(RIGHT($J9,1))) | L9: =SUMIFS($G$5:$G$200,$E$5:$E$200,L$3,$A$5:$A$200,VALUE(RIGHT($J9,1))) | M9: =SUMIFS($G$5:$G$200,$E$5:$E$200,M$3,$A$5:$A$200,VALUE(RIGHT($J9,1))) | N9: =SUMIFS($G$5:$G$200,$E$5:$E$200,N$3,$A$5:$A$200,VALUE(RIGHT($J9,1))) | O9: =SUM(K9:N9) | P9: org - задача организационная, например, проведение meetings, написание отчетов Sprint Review и др.
A10: 1 | B10: 6 | C10: Изучение FastAPI и SQLAlchemy 2.0 | D10: study | E10: Евгений | F10: 3 | G10: 3 | J10: Sprint 7 | K10: =SUMIFS($G$5:$G$200,$E$5:$E$200,K$3,$A$5:$A$200,VALUE(RIGHT($J10,1))) | L10: =SUMIFS($G$5:$G$200,$E$5:$E$200,L$3,$A$5:$A$200,VALUE(RIGHT($J10,1))) | M10: =SUMIFS($G$5:$G$200,$E$5:$E$200,M$3,$A$5:$A$200,VALUE(RIGHT($J10,1))) | N10: =SUMIFS($G$5:$G$200,$E$5:$E$200,N$3,$A$5:$A$200,VALUE(RIGHT($J10,1))) | O10: =SUM(K10:N10)
A11: 1 | B11: 7 | C11: SCRUM-8: Проектирование БД PostgreSQL | D11: BE | E11: Евгений | F11: 5 | G11: 5 | J11: Sprint 8 | K11: =SUMIFS($G$5:$G$200,$E$5:$E$200,K$3,$A$5:$A$200,VALUE(RIGHT($J11,1))) | L11: =SUMIFS($G$5:$G$200,$E$5:$E$200,L$3,$A$5:$A$200,VALUE(RIGHT($J11,1))) | M11: =SUMIFS($G$5:$G$200,$E$5:$E$200,M$3,$A$5:$A$200,VALUE(RIGHT($J11,1))) | N11: =SUMIFS($G$5:$G$200,$E$5:$E$200,N$3,$A$5:$A$200,VALUE(RIGHT($J11,1))) | O11: =SUM(K11:N11) | P11: На основании данных выполнить стат анализ (данные представить с виде графиков также)
A12: 1 | B12: 8 | C12: Изучение React, TypeScript, Vite | D12: study | E12: Тамара | F12: 3 | G12: 3 | J12: Итого | K12: =SUM(K4:K11) | L12: =SUM(L4:L11) | M12: =SUM(M4:M11) | N12: =SUM(N4:N11) | O12: =SUM(K12:N12) | P12: по задачам (время на обучение - время на проект)
A13: 1 | B13: 9 | C13: Каркас SPA, Navbar, react-router | D13: FE | E13: Тамара | F13: 5 | G13: 4.5 | P13: по исполнителям - вклад в работу команды
A14: 1 | B14: 10 | C14: Черновик seed_data.json | D14: doc | E14: Антон | F14: 4 | G14: 3.5 | P14: по категориям - документация, проектирование, кодирование, дизайн, тестирование и др.
A15: 1 | B15: 11 | C15: SCRUM-12: API церковной лавки (не завершено) | D15: BE | E15: Евгений | F15: 4 | G15: 1 | J15: КОМАНДА
A16: 1 | B16: 12 | C16: SCRUM-11: UI каталога лавки (не завершено) | D16: FE | E16: Тамара | F16: 2 | G16: 0.5 | J16: Категории | K16: org | L16: doc | M16: study | N16: BE | O16: FE | P16: tests | Q16: env | R16: Суммарно | S16: %study/project
A17: 2 | B17: 1 | C17: SCRUM-3: Спецификация лавки и треб + seed_data.json | D17: doc | E17: Антон | F17: 6 | G17: 5 | J17: Sprint 1 | K17: =SUMIFS($G$5:$G$200,$D$5:$D$200,K$16,$A$5:$A$200,VALUE(RIGHT($J17,1))) | L17: =SUMIFS($G$5:$G$200,$D$5:$D$200,L$16,$A$5:$A$200,VALUE(RIGHT($J17,1))) | M17: =SUMIFS($G$5:$G$200,$D$5:$D$200,M$16,$A$5:$A$200,VALUE(RIGHT($J17,1))) | N17: =SUMIFS($G$5:$G$200,$D$5:$D$200,N$16,$A$5:$A$200,VALUE(RIGHT($J17,1))) | O17: =SUMIFS($G$5:$G$200,$D$5:$D$200,O$16,$A$5:$A$200,VALUE(RIGHT($J17,1))) | P17: =SUMIFS($G$5:$G$200,$D$5:$D$200,P$16,$A$5:$A$200,VALUE(RIGHT($J17,1))) | Q17: =SUMIFS($G$5:$G$200,$D$5:$D$200,Q$16,$A$5:$A$200,VALUE(RIGHT($J17,1))) | R17: =SUM(K17:Q17) | S17: =IF(R17=0,0,M17/R17)
A18: 2 | B18: 2 | C18: SCRUM-10: Регистрация и авторизация (JWT, роли) | D18: BE | E18: Евгений | F18: 14 | G18: 0 | J18: Sprint 2 | K18: =SUMIFS($G$5:$G$200,$D$5:$D$200,K$16,$A$5:$A$200,VALUE(RIGHT($J18,1))) | L18: =SUMIFS($G$5:$G$200,$D$5:$D$200,L$16,$A$5:$A$200,VALUE(RIGHT($J18,1))) | M18: =SUMIFS($G$5:$G$200,$D$5:$D$200,M$16,$A$5:$A$200,VALUE(RIGHT($J18,1))) | N18: =SUMIFS($G$5:$G$200,$D$5:$D$200,N$16,$A$5:$A$200,VALUE(RIGHT($J18,1))) | O18: =SUMIFS($G$5:$G$200,$D$5:$D$200,O$16,$A$5:$A$200,VALUE(RIGHT($J18,1))) | P18: =SUMIFS($G$5:$G$200,$D$5:$D$200,P$16,$A$5:$A$200,VALUE(RIGHT($J18,1))) | Q18: =SUMIFS($G$5:$G$200,$D$5:$D$200,Q$16,$A$5:$A$200,VALUE(RIGHT($J18,1))) | R18: =SUM(K18:Q18) | S18: =IF(R18=0,0,M18/R18)
A19: 2 | B19: 3 | C19: SCRUM-11: UI каталога церковной лавки | D19: FE | E19: Тамара | F19: 6 | G19: 7 | J19: Sprint 3 | K19: =SUMIFS($G$5:$G$200,$D$5:$D$200,K$16,$A$5:$A$200,VALUE(RIGHT($J19,1))) | L19: =SUMIFS($G$5:$G$200,$D$5:$D$200,L$16,$A$5:$A$200,VALUE(RIGHT($J19,1))) | M19: =SUMIFS($G$5:$G$200,$D$5:$D$200,M$16,$A$5:$A$200,VALUE(RIGHT($J19,1))) | N19: =SUMIFS($G$5:$G$200,$D$5:$D$200,N$16,$A$5:$A$200,VALUE(RIGHT($J19,1))) | O19: =SUMIFS($G$5:$G$200,$D$5:$D$200,O$16,$A$5:$A$200,VALUE(RIGHT($J19,1))) | P19: =SUMIFS($G$5:$G$200,$D$5:$D$200,P$16,$A$5:$A$200,VALUE(RIGHT($J19,1))) | Q19: =SUMIFS($G$5:$G$200,$D$5:$D$200,Q$16,$A$5:$A$200,VALUE(RIGHT($J19,1))) | R19: =SUM(K19:Q19) | S19: =IF(R19=0,0,M19/R19)
A20: 2 | B20: 4 | C20: SCRUM-12: API лавки GET /api/v1/items | D20: BE | E20: Евгений | F20: 10 | G20: 9 | J20: Sprint 4 | K20: =SUMIFS($G$5:$G$200,$D$5:$D$200,K$16,$A$5:$A$200,VALUE(RIGHT($J20,1))) | L20: =SUMIFS($G$5:$G$200,$D$5:$D$200,L$16,$A$5:$A$200,VALUE(RIGHT($J20,1))) | M20: =SUMIFS($G$5:$G$200,$D$5:$D$200,M$16,$A$5:$A$200,VALUE(RIGHT($J20,1))) | N20: =SUMIFS($G$5:$G$200,$D$5:$D$200,N$16,$A$5:$A$200,VALUE(RIGHT($J20,1))) | O20: =SUMIFS($G$5:$G$200,$D$5:$D$200,O$16,$A$5:$A$200,VALUE(RIGHT($J20,1))) | P20: =SUMIFS($G$5:$G$200,$D$5:$D$200,P$16,$A$5:$A$200,VALUE(RIGHT($J20,1))) | Q20: =SUMIFS($G$5:$G$200,$D$5:$D$200,Q$16,$A$5:$A$200,VALUE(RIGHT($J20,1))) | R20: =SUM(K20:Q20) | S20: =IF(R20=0,0,M20/R20)
A21: 2 | B21: 5 | C21: SCRUM-13: Модуль пожертвований (блоки Minecraft) | D21: BE | E21: Евгений | F21: 6 | G21: 6.5 | J21: Sprint 5 | K21: =SUMIFS($G$5:$G$200,$D$5:$D$200,K$16,$A$5:$A$200,VALUE(RIGHT($J21,1))) | L21: =SUMIFS($G$5:$G$200,$D$5:$D$200,L$16,$A$5:$A$200,VALUE(RIGHT($J21,1))) | M21: =SUMIFS($G$5:$G$200,$D$5:$D$200,M$16,$A$5:$A$200,VALUE(RIGHT($J21,1))) | N21: =SUMIFS($G$5:$G$200,$D$5:$D$200,N$16,$A$5:$A$200,VALUE(RIGHT($J21,1))) | O21: =SUMIFS($G$5:$G$200,$D$5:$D$200,O$16,$A$5:$A$200,VALUE(RIGHT($J21,1))) | P21: =SUMIFS($G$5:$G$200,$D$5:$D$200,P$16,$A$5:$A$200,VALUE(RIGHT($J21,1))) | Q21: =SUMIFS($G$5:$G$200,$D$5:$D$200,Q$16,$A$5:$A$200,VALUE(RIGHT($J21,1))) | R21: =SUM(K21:Q21) | S21: =IF(R21=0,0,M21/R21)
A22: 2 | B22: 6 | C22: SCRUM-14: Форма подачи записок (до 15 имён) | D22: FE | E22: Тамара | F22: 10 | G22: 11 | J22: Sprint 6 | K22: =SUMIFS($G$5:$G$200,$D$5:$D$200,K$16,$A$5:$A$200,VALUE(RIGHT($J22,1))) | L22: =SUMIFS($G$5:$G$200,$D$5:$D$200,L$16,$A$5:$A$200,VALUE(RIGHT($J22,1))) | M22: =SUMIFS($G$5:$G$200,$D$5:$D$200,M$16,$A$5:$A$200,VALUE(RIGHT($J22,1))) | N22: =SUMIFS($G$5:$G$200,$D$5:$D$200,N$16,$A$5:$A$200,VALUE(RIGHT($J22,1))) | O22: =SUMIFS($G$5:$G$200,$D$5:$D$200,O$16,$A$5:$A$200,VALUE(RIGHT($J22,1))) | P22: =SUMIFS($G$5:$G$200,$D$5:$D$200,P$16,$A$5:$A$200,VALUE(RIGHT($J22,1))) | Q22: =SUMIFS($G$5:$G$200,$D$5:$D$200,Q$16,$A$5:$A$200,VALUE(RIGHT($J22,1))) | R22: =SUM(K22:Q22) | S22: =IF(R22=0,0,M22/R22)
A23: 2 | B23: 7 | C23: SCRUM-15: Прокси ИИ-консультаций (DeepSeek) | D23: BE | E23: Константин | F23: 16 | G23: 9 | J23: Sprint 7 | K23: =SUMIFS($G$5:$G$200,$D$5:$D$200,K$16,$A$5:$A$200,VALUE(RIGHT($J23,1))) | L23: =SUMIFS($G$5:$G$200,$D$5:$D$200,L$16,$A$5:$A$200,VALUE(RIGHT($J23,1))) | M23: =SUMIFS($G$5:$G$200,$D$5:$D$200,M$16,$A$5:$A$200,VALUE(RIGHT($J23,1))) | N23: =SUMIFS($G$5:$G$200,$D$5:$D$200,N$16,$A$5:$A$200,VALUE(RIGHT($J23,1))) | O23: =SUMIFS($G$5:$G$200,$D$5:$D$200,O$16,$A$5:$A$200,VALUE(RIGHT($J23,1))) | P23: =SUMIFS($G$5:$G$200,$D$5:$D$200,P$16,$A$5:$A$200,VALUE(RIGHT($J23,1))) | Q23: =SUMIFS($G$5:$G$200,$D$5:$D$200,Q$16,$A$5:$A$200,VALUE(RIGHT($J23,1))) | R23: =SUM(K23:Q23) | S23: =IF(R23=0,0,M23/R23)
A24: 2 | B24: 8 | C24: SCRUM-16: ETL Airflow и витрины DWH | D24: BE | E24: Константин | F24: 10 | G24: 10.5 | J24: Sprint 8 | K24: =SUMIFS($G$5:$G$200,$D$5:$D$200,K$16,$A$5:$A$200,VALUE(RIGHT($J24,1))) | L24: =SUMIFS($G$5:$G$200,$D$5:$D$200,L$16,$A$5:$A$200,VALUE(RIGHT($J24,1))) | M24: =SUMIFS($G$5:$G$200,$D$5:$D$200,M$16,$A$5:$A$200,VALUE(RIGHT($J24,1))) | N24: =SUMIFS($G$5:$G$200,$D$5:$D$200,N$16,$A$5:$A$200,VALUE(RIGHT($J24,1))) | O24: =SUMIFS($G$5:$G$200,$D$5:$D$200,O$16,$A$5:$A$200,VALUE(RIGHT($J24,1))) | P24: =SUMIFS($G$5:$G$200,$D$5:$D$200,P$16,$A$5:$A$200,VALUE(RIGHT($J24,1))) | Q24: =SUMIFS($G$5:$G$200,$D$5:$D$200,Q$16,$A$5:$A$200,VALUE(RIGHT($J24,1))) | R24: =SUM(K24:Q24) | S24: =IF(R24=0,0,M24/R24)
A25: 2 | B25: 9 | C25: SCRUM-18: Эндпоинт POST /api/v1/treby | D25: BE | E25: Евгений | F25: 10 | G25: 8.5 | J25: Итого | K25: =SUM(K17:K24) | L25: =SUM(L17:L24) | M25: =SUM(M17:M24) | N25: =SUM(N17:N24) | O25: =SUM(O17:O24) | P25: =SUM(P17:P24) | Q25: =SUM(Q17:Q24) | R25: =SUM(K25:Q25) | S25: =IF(R25=0,0,M25/R25)
A26: 2 | B26: 10 | C26: SCRUM-19: Тест-кейсы валидатора Pydantic | D26: tests | E26: Антон | F26: 6 | G26: 3
A27: 2 | B27: 11 | C27: SCRUM-20: Личный кабинет прихожанина (UI) | D27: FE | E27: Тамара | F27: 10 | G27: 0
A28: 2 | B28: 12 | C28: SCRUM-26: Ручное тестирование и README | D28: tests | E28: Антон | F28: 6 | G28: 0 | J28: Константин
A29: 3 | B29: 1 | C29: SCRUM-10: Регистрация и авторизация (JWT, роли) | D29: BE | E29: Евгений | F29: 10 | G29: 4 | J29: Категории | K29: org | L29: doc | M29: study | N29: BE | O29: FE | P29: tests | Q29: env | R29: Суммарно | S29: %study/project
A30: 3 | B30: 2 | C30: SCRUM-15: Прокси ИИ-консультаций (DeepSeek), остаток | D30: BE | E30: Константин | F30: 7 | G30: 3.5 | J30: Sprint 1 | K30: =SUMIFS($G$5:$G$200,$E$5:$E$200,$J$28,$D$5:$D$200,K$29,$A$5:$A$200,VALUE(RIGHT($J30,1))) | L30: =SUMIFS($G$5:$G$200,$E$5:$E$200,$J$28,$D$5:$D$200,L$29,$A$5:$A$200,VALUE(RIGHT($J30,1))) | M30: =SUMIFS($G$5:$G$200,$E$5:$E$200,$J$28,$D$5:$D$200,M$29,$A$5:$A$200,VALUE(RIGHT($J30,1))) | N30: =SUMIFS($G$5:$G$200,$E$5:$E$200,$J$28,$D$5:$D$200,N$29,$A$5:$A$200,VALUE(RIGHT($J30,1))) | O30: =SUMIFS($G$5:$G$200,$E$5:$E$200,$J$28,$D$5:$D$200,O$29,$A$5:$A$200,VALUE(RIGHT($J30,1))) | P30: =SUMIFS($G$5:$G$200,$E$5:$E$200,$J$28,$D$5:$D$200,P$29,$A$5:$A$200,VALUE(RIGHT($J30,1))) | Q30: =SUMIFS($G$5:$G$200,$E$5:$E$200,$J$28,$D$5:$D$200,Q$29,$A$5:$A$200,VALUE(RIGHT($J30,1))) | R30: =SUM(K30:Q30) | S30: =IF(R30=0,0,M30/R30)
A31: 3 | B31: 3 | C31: SCRUM-20: Личный кабинет прихожанина (UI) | D31: FE | E31: Тамара | F31: 8 | G31: 3 | J31: Sprint 2 | K31: =SUMIFS($G$5:$G$200,$E$5:$E$200,$J$28,$D$5:$D$200,K$29,$A$5:$A$200,VALUE(RIGHT($J31,1))) | L31: =SUMIFS($G$5:$G$200,$E$5:$E$200,$J$28,$D$5:$D$200,L$29,$A$5:$A$200,VALUE(RIGHT($J31,1))) | M31: =SUMIFS($G$5:$G$200,$E$5:$E$200,$J$28,$D$5:$D$200,M$29,$A$5:$A$200,VALUE(RIGHT($J31,1))) | N31: =SUMIFS($G$5:$G$200,$E$5:$E$200,$J$28,$D$5:$D$200,N$29,$A$5:$A$200,VALUE(RIGHT($J31,1))) | O31: =SUMIFS($G$5:$G$200,$E$5:$E$200,$J$28,$D$5:$D$200,O$29,$A$5:$A$200,VALUE(RIGHT($J31,1))) | P31: =SUMIFS($G$5:$G$200,$E$5:$E$200,$J$28,$D$5:$D$200,P$29,$A$5:$A$200,VALUE(RIGHT($J31,1))) | Q31: =SUMIFS($G$5:$G$200,$E$5:$E$200,$J$28,$D$5:$D$200,Q$29,$A$5:$A$200,VALUE(RIGHT($J31,1))) | R31: =SUM(K31:Q31) | S31: =IF(R31=0,0,M31/R31)
A32: 3 | B32: 4 | C32: SCRUM-19: Тест-кейсы валидатора Pydantic | D32: tests | E32: Антон | F32: 2 | G32: 2.5 | J32: Sprint 3 | K32: =SUMIFS($G$5:$G$200,$E$5:$E$200,$J$28,$D$5:$D$200,K$29,$A$5:$A$200,VALUE(RIGHT($J32,1))) | L32: =SUMIFS($G$5:$G$200,$E$5:$E$200,$J$28,$D$5:$D$200,L$29,$A$5:$A$200,VALUE(RIGHT($J32,1))) | M32: =SUMIFS($G$5:$G$200,$E$5:$E$200,$J$28,$D$5:$D$200,M$29,$A$5:$A$200,VALUE(RIGHT($J32,1))) | N32: =SUMIFS($G$5:$G$200,$E$5:$E$200,$J$28,$D$5:$D$200,N$29,$A$5:$A$200,VALUE(RIGHT($J32,1))) | O32: =SUMIFS($G$5:$G$200,$E$5:$E$200,$J$28,$D$5:$D$200,O$29,$A$5:$A$200,VALUE(RIGHT($J32,1))) | P32: =SUMIFS($G$5:$G$200,$E$5:$E$200,$J$28,$D$5:$D$200,P$29,$A$5:$A$200,VALUE(RIGHT($J32,1))) | Q32: =SUMIFS($G$5:$G$200,$E$5:$E$200,$J$28,$D$5:$D$200,Q$29,$A$5:$A$200,VALUE(RIGHT($J32,1))) | R32: =SUM(K32:Q32) | S32: =IF(R32=0,0,M32/R32)
A33: 3 | B33: 5 | C33: SCRUM-26: Ручное тестирование эндпоинтов и README | D33: doc | E33: Антон | F33: 3 | G33: 0 | J33: Sprint 4 | K33: =SUMIFS($G$5:$G$200,$E$5:$E$200,$J$28,$D$5:$D$200,K$29,$A$5:$A$200,VALUE(RIGHT($J33,1))) | L33: =SUMIFS($G$5:$G$200,$E$5:$E$200,$J$28,$D$5:$D$200,L$29,$A$5:$A$200,VALUE(RIGHT($J33,1))) | M33: =SUMIFS($G$5:$G$200,$E$5:$E$200,$J$28,$D$5:$D$200,M$29,$A$5:$A$200,VALUE(RIGHT($J33,1))) | N33: =SUMIFS($G$5:$G$200,$E$5:$E$200,$J$28,$D$5:$D$200,N$29,$A$5:$A$200,VALUE(RIGHT($J33,1))) | O33: =SUMIFS($G$5:$G$200,$E$5:$E$200,$J$28,$D$5:$D$200,O$29,$A$5:$A$200,VALUE(RIGHT($J33,1))) | P33: =SUMIFS($G$5:$G$200,$E$5:$E$200,$J$28,$D$5:$D$200,P$29,$A$5:$A$200,VALUE(RIGHT($J33,1))) | Q33: =SUMIFS($G$5:$G$200,$E$5:$E$200,$J$28,$D$5:$D$200,Q$29,$A$5:$A$200,VALUE(RIGHT($J33,1))) | R33: =SUM(K33:Q33) | S33: =IF(R33=0,0,M33/R33)
A34: 3 | B34: 6 | C34: SCRUM-17: Встреча по визуальному интерфейсу | D34: org | E34: Антон | F34: 1 | G34: 0.75 | J34: Sprint 5 | K34: =SUMIFS($G$5:$G$200,$E$5:$E$200,$J$28,$D$5:$D$200,K$29,$A$5:$A$200,VALUE(RIGHT($J34,1))) | L34: =SUMIFS($G$5:$G$200,$E$5:$E$200,$J$28,$D$5:$D$200,L$29,$A$5:$A$200,VALUE(RIGHT($J34,1))) | M34: =SUMIFS($G$5:$G$200,$E$5:$E$200,$J$28,$D$5:$D$200,M$29,$A$5:$A$200,VALUE(RIGHT($J34,1))) | N34: =SUMIFS($G$5:$G$200,$E$5:$E$200,$J$28,$D$5:$D$200,N$29,$A$5:$A$200,VALUE(RIGHT($J34,1))) | O34: =SUMIFS($G$5:$G$200,$E$5:$E$200,$J$28,$D$5:$D$200,O$29,$A$5:$A$200,VALUE(RIGHT($J34,1))) | P34: =SUMIFS($G$5:$G$200,$E$5:$E$200,$J$28,$D$5:$D$200,P$29,$A$5:$A$200,VALUE(RIGHT($J34,1))) | Q34: =SUMIFS($G$5:$G$200,$E$5:$E$200,$J$28,$D$5:$D$200,Q$29,$A$5:$A$200,VALUE(RIGHT($J34,1))) | R34: =SUM(K34:Q34) | S34: =IF(R34=0,0,M34/R34)
J35: Sprint 6 | K35: =SUMIFS($G$5:$G$200,$E$5:$E$200,$J$28,$D$5:$D$200,K$29,$A$5:$A$200,VALUE(RIGHT($J35,1))) | L35: =SUMIFS($G$5:$G$200,$E$5:$E$200,$J$28,$D$5:$D$200,L$29,$A$5:$A$200,VALUE(RIGHT($J35,1))) | M35: =SUMIFS($G$5:$G$200,$E$5:$E$200,$J$28,$D$5:$D$200,M$29,$A$5:$A$200,VALUE(RIGHT($J35,1))) | N35: =SUMIFS($G$5:$G$200,$E$5:$E$200,$J$28,$D$5:$D$200,N$29,$A$5:$A$200,VALUE(RIGHT($J35,1))) | O35: =SUMIFS($G$5:$G$200,$E$5:$E$200,$J$28,$D$5:$D$200,O$29,$A$5:$A$200,VALUE(RIGHT($J35,1))) | P35: =SUMIFS($G$5:$G$200,$E$5:$E$200,$J$28,$D$5:$D$200,P$29,$A$5:$A$200,VALUE(RIGHT($J35,1))) | Q35: =SUMIFS($G$5:$G$200,$E$5:$E$200,$J$28,$D$5:$D$200,Q$29,$A$5:$A$200,VALUE(RIGHT($J35,1))) | R35: =SUM(K35:Q35) | S35: =IF(R35=0,0,M35/R35)
J36: Sprint 7 | K36: =SUMIFS($G$5:$G$200,$E$5:$E$200,$J$28,$D$5:$D$200,K$29,$A$5:$A$200,VALUE(RIGHT($J36,1))) | L36: =SUMIFS($G$5:$G$200,$E$5:$E$200,$J$28,$D$5:$D$200,L$29,$A$5:$A$200,VALUE(RIGHT($J36,1))) | M36: =SUMIFS($G$5:$G$200,$E$5:$E$200,$J$28,$D$5:$D$200,M$29,$A$5:$A$200,VALUE(RIGHT($J36,1))) | N36: =SUMIFS($G$5:$G$200,$E$5:$E$200,$J$28,$D$5:$D$200,N$29,$A$5:$A$200,VALUE(RIGHT($J36,1))) | O36: =SUMIFS($G$5:$G$200,$E$5:$E$200,$J$28,$D$5:$D$200,O$29,$A$5:$A$200,VALUE(RIGHT($J36,1))) | P36: =SUMIFS($G$5:$G$200,$E$5:$E$200,$J$28,$D$5:$D$200,P$29,$A$5:$A$200,VALUE(RIGHT($J36,1))) | Q36: =SUMIFS($G$5:$G$200,$E$5:$E$200,$J$28,$D$5:$D$200,Q$29,$A$5:$A$200,VALUE(RIGHT($J36,1))) | R36: =SUM(K36:Q36) | S36: =IF(R36=0,0,M36/R36)
J37: Sprint 8 | K37: =SUMIFS($G$5:$G$200,$E$5:$E$200,$J$28,$D$5:$D$200,K$29,$A$5:$A$200,VALUE(RIGHT($J37,1))) | L37: =SUMIFS($G$5:$G$200,$E$5:$E$200,$J$28,$D$5:$D$200,L$29,$A$5:$A$200,VALUE(RIGHT($J37,1))) | M37: =SUMIFS($G$5:$G$200,$E$5:$E$200,$J$28,$D$5:$D$200,M$29,$A$5:$A$200,VALUE(RIGHT($J37,1))) | N37: =SUMIFS($G$5:$G$200,$E$5:$E$200,$J$28,$D$5:$D$200,N$29,$A$5:$A$200,VALUE(RIGHT($J37,1))) | O37: =SUMIFS($G$5:$G$200,$E$5:$E$200,$J$28,$D$5:$D$200,O$29,$A$5:$A$200,VALUE(RIGHT($J37,1))) | P37: =SUMIFS($G$5:$G$200,$E$5:$E$200,$J$28,$D$5:$D$200,P$29,$A$5:$A$200,VALUE(RIGHT($J37,1))) | Q37: =SUMIFS($G$5:$G$200,$E$5:$E$200,$J$28,$D$5:$D$200,Q$29,$A$5:$A$200,VALUE(RIGHT($J37,1))) | R37: =SUM(K37:Q37) | S37: =IF(R37=0,0,M37/R37)
J38: Итого | K38: =SUM(K30:K37) | L38: =SUM(L30:L37) | M38: =SUM(M30:M37) | N38: =SUM(N30:N37) | O38: =SUM(O30:O37) | P38: =SUM(P30:P37) | Q38: =SUM(Q30:Q37) | R38: =SUM(K38:Q38) | S38: =IF(R38=0,0,M38/R38)
J41: Евгений
J42: Категории | K42: org | L42: doc | M42: study | N42: BE | O42: FE | P42: tests | Q42: env | R42: Суммарно | S42: %study/project
...

Sheet Статистика
A1: Статистический анализ (данные из листа «Время работы команды»)
A3: Время по категориям, ч
A4: ='Время работы команды'!K16 | B4: ='Время работы команды'!L16 | C4: ='Время работы команды'!M16 | D4: ='Время работы команды'!N16 | E4: ='Время работы команды'!O16 | F4: ='Время работы команды'!P16 | G4: ='Время работы команды'!Q16
A5: ='Время работы команды'!K25 | B5: ='Время работы команды'!L25 | C5: ='Время работы команды'!M25 | D5: ='Время работы команды'!N25 | E5: ='Время работы команды'!O25 | F5: ='Время работы команды'!P25 | G5: ='Время работы команды'!Q25
A7: Вклад исполнителей, ч
A8: ='Время работы команды'!K3 | B8: ='Время работы команды'!L3 | C8: ='Время работы команды'!M3 | D8: ='Время работы команды'!N3
A9: ='Время работы команды'!K12 | B9: ='Время работы команды'!L12 | C9: ='Время работы команды'!M12 | D9: ='Время работы команды'!N12
A11: Спринт: обучение vs проект, ч
A12: Спринт | B12: Обучение (study) | C12: Проект | D12: % study/project
A13: ='Время работы команды'!J17 | B13: ='Время работы команды'!M17 | C13: ='Время работы команды'!R17-'Время работы команды'!M17 | D13: ='Время работы команды'!S17
A14: ='Время работы команды'!J18 | B14: ='Время работы команды'!M18 | C14: ='Время работы команды'!R18-'Время работы команды'!M18 | D14: ='Время работы команды'!S18
A15: ='Время работы команды'!J19 | B15: ='Время работы команды'!M19 | C15: ='Время работы команды'!R19-'Время работы команды'!M19 | D15: ='Время работы команды'!S19
A16: Планируемое vs реальное время по спринтам, ч
A17: Спринт | B17: План | C17: Факт
A18: ="Sprint "&'Скорость работы команды'!C3 | B18: ='Скорость работы команды'!C8 | C18: ='Скорость работы команды'!C9
A19: ="Sprint "&'Скорость работы команды'!D3 | B19: ='Скорость работы команды'!D8 | C19: ='Скорость работы команды'!D9
A20: ="Sprint "&'Скорость работы команды'!E3 | B20: ='Скорость работы команды'!E8 | C20: ='Скорость работы команды'!E9
